Traceback (most recent call last):
  File "/Users/ashley/anaconda3/envs/jb/lib/python3.11/site-packages/jupyter_cache/executors/utils.py", line 58, in single_nb_execution
    executenb(
  File "/Users/ashley/anaconda3/envs/jb/lib/python3.11/site-packages/nbclient/client.py", line 1305, in execute
    return NotebookClient(nb=nb, resources=resources, km=km, **kwargs).execute()
           ^^^^^^^^^^^^^^^^^^^^^^^^^^^^^^^^^^^^^^^^^^^^^^^^^^^^^^^^^^^^^^^^^^^^^
  File "/Users/ashley/anaconda3/envs/jb/lib/python3.11/site-packages/jupyter_core/utils/__init__.py", line 166, in wrapped
    return loop.run_until_complete(inner)
           ^^^^^^^^^^^^^^^^^^^^^^^^^^^^^^
  File "/Users/ashley/anaconda3/envs/jb/lib/python3.11/asyncio/base_events.py", line 650, in run_until_complete
    return future.result()
           ^^^^^^^^^^^^^^^
  File "/Users/ashley/anaconda3/envs/jb/lib/python3.11/contextlib.py", line 222, in __aexit__
    await self.gen.athrow(typ, value, traceback)
  File "/Users/ashley/anaconda3/envs/jb/lib/python3.11/site-packages/nbclient/client.py", line 650, in async_setup_kernel
    yield
  File "/Users/ashley/anaconda3/envs/jb/lib/python3.11/site-packages/nbclient/client.py", line 705, in async_execute
    await self.async_execute_cell(
  File "/Users/ashley/anaconda3/envs/jb/lib/python3.11/site-packages/nbclient/client.py", line 1058, in async_execute_cell
    await self._check_raise_for_error(cell, cell_index, exec_reply)
  File "/Users/ashley/anaconda3/envs/jb/lib/python3.11/site-packages/nbclient/client.py", line 914, in _check_raise_for_error
    raise CellExecutionError.from_cell_and_msg(cell, exec_reply_content)
nbclient.exceptions.CellExecutionError: An error occurred while executing the following cell:
------------------
# Note: This id is different from our experiment container id 
session_id = experiments[0]['id']
data = boc.get_ophys_experiment_data(session_id)

# Take a look at the kind of object data is 
print(data)
------------------


[0;31m---------------------------------------------------------------------------[0m
[0;31mIndexError[0m                                Traceback (most recent call last)
Cell [0;32mIn[8], line 2[0m
[1;32m      1[0m [38;5;66;03m# Note: This id is different from our experiment container id [39;00m
[0;32m----> 2[0m session_id [38;5;241m=[39m [43mexperiments[49m[43m[[49m[38;5;241;43m0[39;49m[43m][49m[[38;5;124m'[39m[38;5;124mid[39m[38;5;124m'[39m]
[1;32m      3[0m data [38;5;241m=[39m boc[38;5;241m.[39mget_ophys_experiment_data(session_id)
[1;32m      5[0m [38;5;66;03m# Take a look at the kind of object data is [39;00m

[0;31mIndexError[0m: list index out of range

