Traceback (most recent call last):
  File "/Users/ashley/anaconda3/lib/python3.7/site-packages/jupyter_cache/executors/utils.py", line 56, in single_nb_execution
    record_timing=False,
  File "/Users/ashley/anaconda3/lib/python3.7/site-packages/nbclient/client.py", line 1112, in execute
    return NotebookClient(nb=nb, resources=resources, km=km, **kwargs).execute()
  File "/Users/ashley/anaconda3/lib/python3.7/site-packages/nbclient/util.py", line 74, in wrapped
    return just_run(coro(*args, **kwargs))
  File "/Users/ashley/anaconda3/lib/python3.7/site-packages/nbclient/util.py", line 53, in just_run
    return loop.run_until_complete(coro)
  File "/Users/ashley/anaconda3/lib/python3.7/asyncio/base_events.py", line 584, in run_until_complete
    return future.result()
  File "/Users/ashley/anaconda3/lib/python3.7/site-packages/nbclient/client.py", line 554, in async_execute
    cell, index, execution_count=self.code_cells_executed + 1
  File "/Users/ashley/anaconda3/lib/python3.7/site-packages/nbclient/client.py", line 857, in async_execute_cell
    self._check_raise_for_error(cell, exec_reply)
  File "/Users/ashley/anaconda3/lib/python3.7/site-packages/nbclient/client.py", line 760, in _check_raise_for_error
    raise CellExecutionError.from_cell_and_msg(cell, exec_reply_content)
nbclient.exceptions.CellExecutionError: An error occurred while executing the following cell:
------------------
import numpy as np 
import pandas as pd 
from allensdk.core.cell_types_cache import CellTypesCache
from allensdk.api.queries.cell_types_api import CellTypesApi
import matplotlib.pyplot as plt
from scipy import stats 
from scipy import linalg
ctc = CellTypesCache(manifest_file='cell_types/manifest.json')
------------------

[0;31m---------------------------------------------------------------------------[0m
[0;31mModuleNotFoundError[0m                       Traceback (most recent call last)
[0;32m<ipython-input-1-d1e8efc50121>[0m in [0;36m<module>[0;34m[0m
[1;32m      1[0m [0;32mimport[0m [0mnumpy[0m [0;32mas[0m [0mnp[0m[0;34m[0m[0;34m[0m[0m
[1;32m      2[0m [0;32mimport[0m [0mpandas[0m [0;32mas[0m [0mpd[0m[0;34m[0m[0;34m[0m[0m
[0;32m----> 3[0;31m [0;32mfrom[0m [0mallensdk[0m[0;34m.[0m[0mcore[0m[0;34m.[0m[0mcell_types_cache[0m [0;32mimport[0m [0mCellTypesCache[0m[0;34m[0m[0;34m[0m[0m
[0m[1;32m      4[0m [0;32mfrom[0m [0mallensdk[0m[0;34m.[0m[0mapi[0m[0;34m.[0m[0mqueries[0m[0;34m.[0m[0mcell_types_api[0m [0;32mimport[0m [0mCellTypesApi[0m[0;34m[0m[0;34m[0m[0m
[1;32m      5[0m [0;32mimport[0m [0mmatplotlib[0m[0;34m.[0m[0mpyplot[0m [0;32mas[0m [0mplt[0m[0;34m[0m[0;34m[0m[0m

[0;32m~/anaconda3/lib/python3.7/site-packages/allensdk/core/cell_types_cache.py[0m in [0;36m<module>[0;34m[0m
[1;32m     42[0m [0;34m[0m[0m
[1;32m     43[0m [0;32mfrom[0m [0;34m.[0m [0;32mimport[0m [0mjson_utilities[0m [0;32mas[0m [0mjson_utilities[0m[0;34m[0m[0;34m[0m[0m
[0;32m---> 44[0;31m [0;32mfrom[0m [0;34m.[0m[0mnwb_data_set[0m [0;32mimport[0m [0mNwbDataSet[0m[0;34m[0m[0;34m[0m[0m
[0m[1;32m     45[0m [0;32mfrom[0m [0;34m.[0m [0;32mimport[0m  [0mswc[0m[0;34m[0m[0;34m[0m[0m
[1;32m     46[0m [0;34m[0m[0m

[0;32m~/anaconda3/lib/python3.7/site-packages/allensdk/core/nwb_data_set.py[0m in [0;36m<module>[0;34m[0m
[1;32m     34[0m [0;31m# POSSIBILITY OF SUCH DAMAGE.[0m[0;34m[0m[0;34m[0m[0;34m[0m[0m
[1;32m     35[0m [0;31m#[0m[0;34m[0m[0;34m[0m[0;34m[0m[0m
[0;32m---> 36[0;31m [0;32mimport[0m [0mh5py[0m[0;34m[0m[0;34m[0m[0m
[0m[1;32m     37[0m [0;32mimport[0m [0mnumpy[0m [0;32mas[0m [0mnp[0m[0;34m[0m[0;34m[0m[0m
[1;32m     38[0m [0;34m[0m[0m

[0;31mModuleNotFoundError[0m: No module named 'h5py'
ModuleNotFoundError: No module named 'h5py'

